<robot name = "robot">
    <link name="Link1">
        <inertial>
            <origin xyz="0 -0.21638080093160506 0" rpy="0 0 0"/>
            <mass value="1" />
            <inertia ixx="100" ixy="0" ixz="0" iyy="100" iyz="0" izz="100" />
        </inertial>
        <visual>
            <origin xyz="0 -0.21638080093160506 0" rpy="0 0 0"/>
            <geometry>
                <box size="2.6693821361734678 0.4327616018632101 1.7711267594879887" />
            </geometry>
            <material name="Green">
                <color rgba="0 1 0 1.0"/>
            </material>
        </visual>
        <collision>
            <origin xyz="0 -0.21638080093160506 0" rpy="0 0 0"/>
            <geometry>
                <box size="2.6693821361734678 0.4327616018632101 1.7711267594879887" />
            </geometry>
        </collision>
    </link>
    <joint name="Link1_Link2" type="revolute">
       <parent link="Link1"/>
       <child  link="Link2"/>
       <origin rpy="0 0 0" xyz="0.2819731415156157 -1.0622214044388734 -0.8855633797439943" />
     <axis xyz="0 1 0"/>
       <limit effort="0.0" lower="-3.14159" upper="3.14159" velocity="0.0"/>
    </joint>
    <link name="Link2">
        <inertial>
            <origin xyz="0 0 -0.5024617837728833" rpy="0 0 0"/>
            <mass value="1" />
            <inertia ixx="100" ixy="0" ixz="0" iyy="100" iyz="0" izz="100" />
        </inertial>
        <visual>
            <origin xyz="0 0 -0.5024617837728833" rpy="0 0 0"/>
            <geometry>
                <box size="0.759066480266209 2.8889208543379343 1.0049235675457666" />
            </geometry>
            <material name="Green">
                <color rgba="0 1 0 1.0"/>
            </material>
        </visual>
        <collision>
            <origin xyz="0 0 -0.5024617837728833" rpy="0 0 0"/>
            <geometry>
                <box size="0.759066480266209 2.8889208543379343 1.0049235675457666" />
            </geometry>
        </collision>
    </link>
    <joint name="Link2_Link3" type="revolute">
       <parent link="Link2"/>
       <child  link="Link3"/>
       <origin rpy="0 0 0" xyz="-0.3795332401331045 0.6885085974579028 -0.5011749405924517" />
     <axis xyz="0 1 0"/>
       <limit effort="0.0" lower="-3.14159" upper="3.14159" velocity="0.0"/>
    </joint>
    <link name="Link3">
        <inertial>
            <origin xyz="-0.20414806495419585 0 0" rpy="0 0 0"/>
            <mass value="1" />
            <inertia ixx="100" ixy="0" ixz="0" iyy="100" iyz="0" izz="100" />
        </inertial>
        <visual>
            <origin xyz="-0.20414806495419585 0 0" rpy="0 0 0"/>
            <geometry>
                <box size="0.4082961299083917 2.251485945013828 0.2940264216787285" />
            </geometry>
            <material name="Blue">
                <color rgba="0 0 1 1.0"/>
            </material>
        </visual>
        <collision>
            <origin xyz="-0.20414806495419585 0 0" rpy="0 0 0"/>
            <geometry>
                <box size="0.4082961299083917 2.251485945013828 0.2940264216787285" />
            </geometry>
        </collision>
    </link>
    <joint name="Link3_Link4" type="revolute">
       <parent link="Link3"/>
       <child  link="Link4"/>
       <origin rpy="0 0 0" xyz="-1.1920359920542152 1.125742972506914 -0.037965798165469855" />
     <axis xyz="0 1 0"/>
       <limit effort="0.0" lower="-3.14159" upper="3.14159" velocity="0.0"/>
    </joint>
    <link name="Link4">
        <inertial>
            <origin xyz="0 0.6968430722746619 0" rpy="0 0 0"/>
            <mass value="1" />
            <inertia ixx="100" ixy="0" ixz="0" iyy="100" iyz="0" izz="100" />
        </inertial>
        <visual>
            <origin xyz="0 0.6968430722746619 0" rpy="0 0 0"/>
            <geometry>
                <box size="0.8183941373261797 1.3936861445493238 1.444172760135227" />
            </geometry>
            <material name="Green">
                <color rgba="0 1 0 1.0"/>
            </material>
        </visual>
        <collision>
            <origin xyz="0 0.6968430722746619 0" rpy="0 0 0"/>
            <geometry>
                <box size="0.8183941373261797 1.3936861445493238 1.444172760135227" />
            </geometry>
        </collision>
    </link>
    <link name="Link0">
        <inertial>
            <origin xyz="0 0 2.6467904985695294" rpy="0 0 0"/>
            <mass value="1" />
            <inertia ixx="100" ixy="0" ixz="0" iyy="100" iyz="0" izz="100" />
        </inertial>
        <visual>
            <origin xyz="0 0 2.6467904985695294" rpy="0 0 0"/>
            <geometry>
                <box size="1 1 1" />
            </geometry>
            <material name="Green">
                <color rgba="0 1 0 1.0"/>
            </material>
        </visual>
        <collision>
            <origin xyz="0 0 2.6467904985695294" rpy="0 0 0"/>
            <geometry>
                <box size="1 1 1" />
            </geometry>
        </collision>
    </link>
    <joint name="Link0_Link1" type="revolute">
       <parent link="Link0"/>
       <child  link="Link1"/>
       <origin rpy="0 0 0" xyz="0 -0.5 2.6467904985695294" />
     <axis xyz="0 1 0"/>
       <limit effort="0.0" lower="-3.14159" upper="3.14159" velocity="0.0"/>
    </joint>
</robot>